Workbook
Name active: [1]Assumptions!$I$25:$I$30
Name active: #REF!
Name AddressOfCells: _xlfn.LAMBDA(_xlpm.Array,_xlfn.MAP(_xlpm.Array,_xlfn.LAMBDA(_xlpm.a,ADDRESS(ROW(_xlpm.a),COLUMN(_xlpm.a),4))))
Name AddressOfCells: _xlfn.LAMBDA(_xlpm.Array,_xlfn.MAP(_xlpm.Array,_xlfn.LAMBDA(_xlpm.a,ADDRESS(ROW(_xlpm.a),COLUMN(_xlpm.a),4))))
Name Alphabet: _xlfn.LAMBDA(CHAR(_xlfn.SEQUENCE(26,,65)))
Name AlphaShift: _xlfn.LAMBDA(_xlpm.startcode,_xlpm.adjustment,_xlpm.startingletter,MOD(_xlpm.startcode+_xlpm.adjustment-_xlpm.startingletter,26)+_xlpm.startingletter)
Name AlphaShift: _xlfn.LAMBDA(_xlpm.startcode,_xlpm.adjustment,_xlpm.startingletter,MOD(_xlpm.startcode+_xlpm.adjustment-_xlpm.startingletter,26)+_xlpm.startingletter)
Name Arrows: _xlfn.LAMBDA(_xlop.ShowHV,IF(_xlpm.ShowHV,{"↓",1,0;"↑",-1,0;"→",0,1;"←",0,-1;"↘",1,1;"↖",-1,-1;"↙",1,-1;"↗",-1,1},{"↓";"↑";"→";"←";"↘";"↖";"↙";"↗"}))
Name Arrows: _xlfn.LAMBDA(_xlop.ShowHV,IF(_xlpm.ShowHV,{"↓",1,0;"↑",-1,0;"→",0,1;"←",0,-1;"↘",1,1;"↖",-1,-1;"↙",1,-1;"↗",-1,1},{"↓";"↑";"→";"←";"↘";"↖";"↙";"↗"}))
Name BoardGameMove: _xlfn.LAMBDA(_xlpm.MoveValue,_xlpm.EndSpace,MOD(_xlpm.MoveValue-1,_xlpm.EndSpace)+1)
Name BoardGameMove: _xlfn.LAMBDA(_xlpm.MoveValue,_xlpm.EndSpace,MOD(_xlpm.MoveValue-1,_xlpm.EndSpace)+1)
Name Creatures: #REF!
Name cust: [1]Assumptions!$B$25:$B$30
Name cust: #REF!
Name DiceNumExtract: _xlfn.LAMBDA(_xlpm.Dice,_xlfn.UNICODE(_xlpm.Dice)-9855)
Name DiceNumExtract: _xlfn.LAMBDA(_xlpm.Dice,_xlfn.UNICODE(_xlpm.Dice)-9855)
Name Exists: _xlfn.LAMBDA(_xlpm.Item,_xlpm.List,_xlop.SearchMode,ISNUMBER(IF(_xlpm.SearchMode,_xleta.SEARCH,_xleta.XMATCH)(_xlpm.Item,_xlpm.List)))
Name Exists: _xlfn.LAMBDA(_xlpm.Item,_xlpm.List,_xlop.SearchMode,ISNUMBER(IF(_xlpm.SearchMode,_xleta.SEARCH,_xleta.XMATCH)(_xlpm.Item,_xlpm.List)))
Name ib_rate: [1]Assumptions!$H$25:$H$30
Name ib_rate: #REF!
Name inpal: [1]Assumptions!$G$25:$G$30
Name inpal: #REF!
Name month: [1]Assumptions!$D$25:$D$30
Name month: #REF!
Name pal: #REF!
Name PPP: [1]Assumptions!$F$25:$F$30
Name PPP: #REF!
Name RowNum: _xlfn.LAMBDA(_xlpm.addresses,IF(ISNUMBER(_xlpm.addresses),INT(_xlpm.addresses/10^6),1*_xlfn.TEXTAFTER(UPPER(_xlpm.addresses),Alphabet(),-1)))
Name RowNum: _xlfn.LAMBDA(_xlpm.addresses,IF(ISNUMBER(_xlpm.addresses),INT(_xlpm.addresses/10^6),1*_xlfn.TEXTAFTER(UPPER(_xlpm.addresses),Alphabet(),-1)))
Name seg: [1]Assumptions!$C$25:$C$30
Name seg: #REF!
Name starting_parc: [1]Assumptions!$E$25:$E$30
Name starting_parc: #REF!
Name Tlookup: _xlfn.LAMBDA(_xlpm.Table,_xlpm.Rowitem,_xlpm.Columnitem,INDEX(_xlpm.Table,_xlfn.XMATCH(_xlpm.Rowitem,_xlfn.TAKE(_xlpm.Table,,1)),_xlfn.XMATCH(_xlpm.Columnitem,_xlfn.TAKE(_xlpm.Table,1))))
Name Tlookup: _xlfn.LAMBDA(_xlpm.Table,_xlpm.Rowitem,_xlpm.Columnitem,INDEX(_xlpm.Table,_xlfn.XMATCH(_xlpm.Rowitem,_xlfn.TAKE(_xlpm.Table,,1)),_xlfn.XMATCH(_xlpm.Columnitem,_xlfn.TAKE(_xlpm.Table,1))))

Sheet Cover
C1: 5-Year 3-Statement Financial Model for Retail Store Network
C2: 5-Year Monthly Financial Projection Model
C3: 3-Statement Model Forecast | Store Expansion Evaluation | 60-Month Projection Horizon
C6: Model Purpose: | D6: 5-year 3-Statement Financial Model
C7: Projection Period: | D7: January 2026 — December 2030 (60 months)
C8: Industries: | D8: Retail | Multi-Store Network
C9: Revenue Lines: | D9: Device Sales · Accessory Sales · Mobile Plan Subscriptions
C10: Built By: | D10: Alicia Bruce
C11: Competition: | D11: Financial Modeling World Cup (FMWC) Case By Andrew Grigolyunovich, CFA, MFM
A13: Built using a Financial Modeling World Cup case. Synthetic data — for portfolio demonstration purposes only.

Sheet Dashboard Summary
B1: TeleKings Inc. Dashboard
B5: 5 Year Totals
B6: Revenue | C6: =SUM(Model!H20:BO20) -> 8000721.9
B7: EBITDA | C7: =SUM(Model!H38:BO38) -> 620332.42
B8: EBITDA Percentage | C8: =C7/C6 -> 0.077534556
B9: Net Income | C9: =SUM(_xlfn.ANCHORARRAY(Model!H52)) -> 403105.96
B10: Ending Cash Balance | C10: =Model!BO112 -> 266695
B11: Ending Debt | C11: =Model!BO78 -> 18750
B12: Total Cities | C12: =COUNTA(_xlfn.ANCHORARRAY(Model!C127)) -> 26
B13: Total Stores | C13: =Model!BO153 -> 1060
B14: =Model!B4 -> [in thousands of $]
B19: Store Metrics | D19: City Metrics (select City below)
B20: Average Stores Per City | C20: =C13/C12 -> 40.769231 | D20: Axisbyte
B21: Median Stores Per City | C21: =MEDIAN(Model!BO127:BO152) -> 9 | D21: Number of Stores | E21: =_xlfn.XLOOKUP('Dashboard Summary'!D20,Model!C127:C153,Model!BO127:BO153) -> 9
B22: Average Revenue Per City | C22: =C6/C12 -> 307720.07 | D22: City Revenue | E22: =SUMIF(Model!C218:BO243,'Dashboard Summary'!D20,Model!H218:BO243)+SUMIF(Model!C247:BO272,'Dashboard Summary'!D20,Model!H247:BO272)+SUMIF(Model!C280:BO305,'Dashboard Summary'!D20,Model!H280:BO305) -> 845.20427
B23: Average Revenue Per Store | C23: =C6/C13 -> 7547.8508 | D23: City Revenue Per Store | E23: =E22/E21 -> 93.911585
B24: Number of Cannibalized Cities | C24: =COUNTIF(Model!BO156:BO181,"<=10000") -> 6 | D24: Cannibalized City | E24: {=IF(_xlfn.XLOOKUP(D20,_xlfn.ANCHORARRAY(Model!C188),Model!BO188:BO213)=1,"No","Yes")} -> No
B25: [in thousands of $]

Sheet Assumptions
B2: Retail Kings
B3: Inputs and Assumptions
B6: 1. General & Sales Assumptions | F6: 2. Demographic Data
B8: General Assumptions | F8: City | H8: Population
B9: Company Name | C9: [Date] | D9: TeleKings | F9: Axisbyte | G9: [ppl] | H9: 380887
B10: First Date of Projections | C10: [Date] | D10: 46023 | F10: Bootwell | G10: [ppl] | H10: 540720
B11: Annual Inflation | C11: [% p.a.] | D11: 0.03 | F11: Cacheford | G11: [ppl] | H11: 56314
F12: Datahaven | G12: [ppl] | H12: 773777
B13: Gross Profitability | F13: Etherport | G13: [ppl] | H13: 93924
B14: Plan Activation Commission | C14: [$/Unit] | D14: 100 | F14: Fiberfall | G14: [ppl] | H14: 38112
B15: Device Sales - Gross Margin | C15: [%] | D15: 0.1 | F15: Gigatown | G15: [ppl] | H15: 2668971
B16: Accessory Sales - Gross Margin | C16: [%] | D16: 0.7 | F16: Hexavale | G16: [ppl] | H16: 17532542
F17: Input City | G17: [ppl] | H17: 871720
B18: Sales Seasonality (% of Average) | F18: Junction Core | G18: [ppl] | H18: 129351
B19: January | C19: [%] | D19: 0.8 | F19: Kernel Heights | G19: [ppl] | H19: 67975
B20: February | C20: [%] | D20: 0.75 | F20: Logicridge | G20: [ppl] | H20: 225699
B21: March | C21: [%] | D21: 1 | F21: Megahub | G21: [ppl] | H21: 11546
B22: April | C22: [%] | D22: 1 | F22: Nodeline | G22: [ppl] | H22: 357386
B23: May | C23: [%] | D23: 1 | F23: Overclock Oasis | G23: [ppl] | H23: 2864910
B24: June | C24: [%] | D24: 1 | F24: Pingborough | G24: [ppl] | H24: 46298
B25: July | C25: [%] | D25: 1 | F25: Quantum Quay | G25: [ppl] | H25: 279623
B26: August | C26: [%] | D26: 1 | F26: Renderburg | G26: [ppl] | H26: 4725450
B27: September | C27: [%] | D27: 1 | F27: Socket Springs | G27: [ppl] | H27: 7896730
B28: October | C28: [%] | D28: 1 | F28: TerraTask | G28: [ppl] | H28: 2383564
B29: November | C29: [%] | D29: 1 | F29: Uploadia | G29: [ppl] | H29: 12705
B30: December | C30: [%] | D30: 1.5 | F30: Vector Valley | G30: [ppl] | H30: 558221
F31: Wiredown | G31: [ppl] | H31: 351937
B32: Operating Expenses | F32: Xenocode City | G32: [ppl] | H32: 41805
B33: Hours per month per Full-Time Equivalent | C33: [h/mo/FTE] | D33: 160 | F33: Yieldville | G33: [ppl] | H33: 68307
B34: Sales Personnel Average Hourly Rate | C34: [$/h] | D34: 15 | F34: ZeroDay Zone | G34: [ppl] | H34: 60150
B35: Other Sales Expenses per Store | C35: [$/mo/Store] | D35: 1000
B36: General & Administrative Expenses | C36: [$k/mo] | D36: 5000
B38: New Store Data | F38: Store Cannibalization Penalty
B39: CAPEX per New Store | C39: [$k/Store] | D39: 100 | F39: City Inhabitants per Store Threshhold | G39: [ppl] | H39: 10000
B40: Sales Personnel per New Store | C40: [FTE/Store] | D40: 3 | F40: Penalty | G40: [%] | H40: -0.2
B41: G&A Expense Increase per New Store | C41: [$k/Store] | D41: 2
B44: 3. Balance Sheet Assumptions
B46: Selected Balance Sheet Items as of 12/31/2025 | F46: Fixed Asset Assumptions
B47: Cash Balance | C47: [$k] | D47: 10000 | F47: CAPEX per New Store | G47: [$k/Store] | H47: =D39 -> 100
B48: Accounts Receivable | C48: [$k] | D48: 90000 | F48: Depreciation - Existing PP&E (SL) | G48: [Years] | H48: 3
...

Sheet Existing Stores
B2: TeleKings
B3: Existing Store Sales - Monthly Averages 2025
B5: Existing Store Sales - Monthly Averages 2025 | I5: Existing Store Expense Data 2025
B7: # | C7: Store Name | D7: City | E7: Mobile Plans | F7: Device Sales | G7: Accessory Sales | I7: # of Employees (FTE) | J7: Monthly Rent & Utilities
C8: [Name] | D8: [Name] | E8: [Units] | F8: [$k] | G8: [$k] | I8: [FTE] | J8: [$k]
B9: {=_xlfn.SEQUENCE(1000)} -> 1 | C9: Junction Core Center Outlet | D9: Junction Core | E9: 42 | F9: 64.1 | G9: 9 | I9: =IF(F9<=100,3,IF(F9<=140,4,IF(F9<=175,5,6))) -> 3 | J9: 2.22427 | L9: {=_xlfn.GROUPBY(D9:D1008,E9:E1008,_xleta.COUNT)} -> Axisbyte | M9: 6
B10: 2 | C10: Socket Springs Solutions Center | D10: Socket Springs | E10: 72 | F10: 129.9 | G10: 21 | I10: =IF(F10<=100,3,IF(F10<=140,4,IF(F10<=175,5,6))) -> 4 | J10: 3.15657 | L10: Bootwell | M10: 30
B11: 3 | C11: Socket Springs Hub Wireless | D11: Socket Springs | E11: 62 | F11: 79.7 | G11: 9 | I11: =IF(F11<=100,3,IF(F11<=140,4,IF(F11<=175,5,6))) -> 3 | J11: 2.68589 | L11: Cacheford | M11: 5
B12: 4 | C12: Hexavale Digital Retail Outlet | D12: Hexavale | E12: 47 | F12: 64.5 | G12: 10 | I12: =IF(F12<=100,3,IF(F12<=140,4,IF(F12<=175,5,6))) -> 3 | J12: 1.6512 | L12: Datahaven | M12: 22
B13: 5 | C13: Hexavale Plaza Retail | D13: Hexavale | E13: 94 | F13: 132.6 | G13: 13 | I13: =IF(F13<=100,3,IF(F13<=140,4,IF(F13<=175,5,6))) -> 4 | J13: 5.304 | L13: Etherport | M13: 3
B14: 6 | C14: Renderburg Connect Store | D14: Renderburg | E14: 39 | F14: 52.2 | G14: 7 | I14: =IF(F14<=100,3,IF(F14<=140,4,IF(F14<=175,5,6))) -> 3 | J14: 1.90008 | L14: Fiberfall | M14: 3
B15: 7 | C15: Quantum Quay Link Hub | D15: Quantum Quay | E15: 76 | F15: 142.6 | G15: 19 | I15: =IF(F15<=100,3,IF(F15<=140,4,IF(F15<=175,5,6))) -> 5 | J15: 3.79316 | L15: Gigatown | M15: 65
B16: 8 | C16: Gigatown Market Mega Center | D16: Gigatown | E16: 55 | F16: 80.5 | G16: 10 | I16: =IF(F16<=100,3,IF(F16<=140,4,IF(F16<=175,5,6))) -> 3 | J16: 2.16545 | L16: Hexavale | M16: 311
B17: 9 | C17: Vector Valley Corner Retail | D17: Vector Valley | E17: 59 | F17: 113.2 | G17: 19 | I17: =IF(F17<=100,3,IF(F17<=140,4,IF(F17<=175,5,6))) -> 4 | J17: 2.73944 | L17: Input City | M17: 17
B18: 10 | C18: Hexavale Pulse Retail Outlet | D18: Hexavale | E18: 73 | F18: 122.6 | G18: 21 | I18: =IF(F18<=100,3,IF(F18<=140,4,IF(F18<=175,5,6))) -> 4 | J18: 4.57298 | L18: Junction Core | M18: 8
B19: 11 | C19: Datahaven Square Express | D19: Datahaven | E19: 95 | F19: 157.2 | G19: 19 | I19: =IF(F19<=100,3,IF(F19<=140,4,IF(F19<=175,5,6))) -> 5 | J19: 4.13436 | L19: Kernel Heights | M19: 3
B20: 12 | C20: Overclock Oasis Max Kiosk | D20: Overclock Oasis | E20: 68 | F20: 97.6 | G20: 14 | I20: =IF(F20<=100,3,IF(F20<=140,4,IF(F20<=175,5,6))) -> 3 | J20: 3.54288 | L20: Logicridge | M20: 5
B21: 13 | C21: Hexavale Spot Store | D21: Hexavale | E21: 84 | F21: 105.3 | G21: 20 | I21: =IF(F21<=100,3,IF(F21<=140,4,IF(F21<=175,5,6))) -> 4 | J21: 2.92734 | L21: Megahub | M21: 1
... B35: 27 | C35: Datahaven Metro Kiosk | D35: Datahaven | E35: 39 | F35: 65.6 | G35: 8 | I35: =IF(F35<=100,3,IF(F35<=140,4,IF(F35<=175,5,6))) -> 3 | J35: 1.82368 | L35: Total | M35: 1000
B36: 28 | C36: Hexavale Pro Center | D36: Hexavale | E36: 59 | F36: 67.4 | G36: 10 | I36: =IF(F36<=100,3,IF(F36<=140,4,IF(F36<=175,5,6))) -> 3 | J36: 1.53672
B37: 29 | C37: TerraTask Retail Kiosk | D37: TerraTask | E37: 85 | F37: 101 | G37: 11 | I37: =IF(F37<=100,3,IF(F37<=140,4,IF(F37<=175,5,6))) -> 4 | J37: 3.9491
B38: 30 | C38: Socket Springs World Kiosk | D38: Socket Springs | E38: 90 | F38: 130.4 | G38: 14 | I38: =IF(F38<=100,3,IF(F38<=140,4,IF(F38<=175,5,6))) -> 4 | J38: 5.09864
B39: 31 | C39: Socket Springs One Express | D39: Socket Springs | E39: 89 | F39: 155.7 | G39: 25 | I39: =IF(F39<=100,3,IF(F39<=140,4,IF(F39<=175,5,6))) -> 5 | J39: 5.24709
B40: 32 | C40: Hexavale Corner Retail Center | D40: Hexavale | E40: 59 | F40: 109.3 | G40: 19 | I40: =IF(F40<=100,3,IF(F40<=140,4,IF(F40<=175,5,6))) -> 4 | J40: 3.10412
B41: 33 | C41: Gigatown Max Wireless | D41: Gigatown | E41: 47 | F41: 50.1 | G41: 6 | I41: =IF(F41<=100,3,IF(F41<=140,4,IF(F41<=175,5,6))) -> 3 | J41: 1.86873
B42: 34 | C42: Hexavale Metro Retail Center | D42: Hexavale | E42: 58 | F42: 97.7 | G42: 12 | I42: =IF(F42<=100,3,IF(F42<=140,4,IF(F42<=175,5,6))) -> 3 | J42: 2.40342
B43: 35 | C43: Hexavale Center | D43: Hexavale | E43: 41 | F43: 62.3 | G43: 9 | I43: =IF(F43<=100,3,IF(F43<=140,4,IF(F43<=175,5,6))) -> 3 | J43: 2.33002
B44: 36 | C44: Hexavale Corner Small Kiosk | D44: Hexavale | E44: 67 | F44: 127.5 | G44: 26 | I44: =IF(F44<=100,3,IF(F44<=140,4,IF(F44<=175,5,6))) -> 4 | J44: 2.66475
B45: 37 | C45: Overclock Oasis Wave Retail Outlet | D45: Overclock Oasis | E45: 46 | F45: 59.2 | G45: 6 | I45: =IF(F45<=100,3,IF(F45<=140,4,IF(F45<=175,5,6))) -> 3 | J45: 1.26688
B46: 38 | C46: Hexavale Solutions Wireless Center | D46: Hexavale | E46: 43 | F46: 83.6 | G46: 10 | I46: =IF(F46<=100,3,IF(F46<=140,4,IF(F46<=175,5,6))) -> 3 | J46: 2.717
B47: 39 | C47: Socket Springs Edge Retail | D47: Socket Springs | E47: 69 | F47: 72.1 | G47: 9 | I47: =IF(F47<=100,3,IF(F47<=140,4,IF(F47<=175,5,6))) -> 3 | J47: 2.01159
... B1008: 1000 | C1008: Vector Valley Pulse Wireless | D1008: Vector Valley | E1008: 54 | F1008: 58 | G1008: 8 | I1008: =IF(F1008<=100,3,IF(F1008<=140,4,IF(F1008<=175,5,6))) -> 3 | J1008: 1.3978
C1009: Total Current Assets | E1009: =SUM(E9:E1008) -> 64633 | F1009: =SUM(F9:F1008) -> 96997.2 | G1009: =SUM(G9:G1008) -> 14678 | I1009: =SUM(I9:I1008) -> 3544 | J1009: =SUM(J9:J1008) -> 2917.1002

Sheet Model
B3: TeleKings Inc. - 5 Year Financial Projection
B4: [in thousands of $]
C6: Period Number | G6: {=_xlfn.SEQUENCE(,61,0)} -> 0 | H6: 1 | I6: 2 | J6: 3 | K6: 4 | L6: 5 | M6: 6 | N6: 7 | O6: 8 | P6: 9 | Q6: 10 | R6: 11 | S6: 12 | T6: 13 | U6: 14 | V6: 15 | W6: 16 | X6: 17 | Y6: 18 | Z6: 19 | AA6: 20 | AB6: 21 | AC6: 22 | AD6: 23 | AE6: 24 | AF6: 25 | AG6: 26 | AH6: 27 | AI6: 28 | AJ6: 29 | AK6: 30 | AL6: 31 | AM6: 32 | AN6: 33 | AO6: 34 | AP6: 35 | AQ6: 36 | AR6: 37 | AS6: 38 | AT6: 39 | AU6: 40 | AV6: 41 | AW6: 42 | AX6: 43 | AY6: 44 | AZ6: 45 | BA6: 46 | BB6: 47 | BC6: 48 | BD6: 49 | BE6: 50 | BF6: 51 | BG6: 52 | BH6: 53 | BI6: 54 | BJ6: 55 | BK6: 56 | BL6: 57 | BM6: 58 | BN6: 59 | BO6: 60
C7: Period Start | G7: 45992 | H7: =Assumptions!D10 -> 46023 | I7: =+H8+1 -> 46054 | J7: =+I8+1 -> 46082 | K7: =+J8+1 -> 46113 | L7: =+K8+1 -> 46143 | M7: =+L8+1 -> 46174 | N7: =+M8+1 -> 46204 | O7: =+N8+1 -> 46235 | P7: =+O8+1 -> 46266 | ... BO7: =+BN8+1 -> 47818
C8: Period End | G8: 46022 | H8: =EOMONTH(H7,0) -> 46053 | I8: =EOMONTH(I7,0) -> 46081 | J8: =EOMONTH(J7,0) -> 46112 | K8: =EOMONTH(K7,0) -> 46142 | L8: =EOMONTH(L7,0) -> 46173 | M8: =EOMONTH(M7,0) -> 46203 | N8: =EOMONTH(N7,0) -> 46234 | O8: =EOMONTH(O7,0) -> 46265 | ... BO8: =EOMONTH(BO7,0) -> 47848
C9: Month | G9: {=MONTH(G8:BO8)} -> 12 | H9: 1 | I9: 2 | J9: 3 | K9: 4 | L9: 5 | M9: 6 | N9: 7 | O9: 8 | P9: 9 | Q9: 10 | R9: 11 | S9: 12 | T9: 1 | U9: 2 | V9: 3 | W9: 4 | X9: 5 | Y9: 6 | Z9: 7 | AA9: 8 | AB9: 9 | AC9: 10 | AD9: 11 | AE9: 12 | AF9: 1 | AG9: 2 | AH9: 3 | AI9: 4 | AJ9: 5 | AK9: 6 | AL9: 7 | AM9: 8 | AN9: 9 | AO9: 10 | AP9: 11 | AQ9: 12 | AR9: 1 | AS9: 2 | AT9: 3 | AU9: 4 | AV9: 5 | AW9: 6 | AX9: 7 | AY9: 8 | AZ9: 9 | BA9: 10 | BB9: 11 | BC9: 12 | BD9: 1 | BE9: 2 | BF9: 3 | BG9: 4 | BH9: 5 | BI9: 6 | BJ9: 7 | BK9: 8 | BL9: 9 | BM9: 10 | BN9: 11 | BO9: 12
C10: Month Name | G10: {=TEXT(G8:BO8,"MMMM")} -> December | H10: January | I10: February | J10: March | K10: April | L10: May | M10: June | N10: July | O10: August | P10: September | Q10: October | R10: November | S10: December | T10: January | U10: February | V10: March | W10: April | X10: May | Y10: June | Z10: July | AA10: August | AB10: September | AC10: October | AD10: November | AE10: December | AF10: January | AG10: February | AH10: March | AI10: April | AJ10: May | AK10: June | AL10: July | AM10: August | AN10: September | AO10: October | AP10: November | AQ10: December | AR10: January | AS10: February | AT10: March | AU10: April | AV10: May | AW10: June | AX10: July | AY10: August | AZ10: September | BA10: October | BB10: November | BC10: December | BD10: January | BE10: February | BF10: March | BG10: April | BH10: May | BI10: June | BJ10: July | BK10: August | BL10: September | BM10: October | BN10: November | BO10: December
C11: Year | G11: {=YEAR(G8:BO8)} -> 2025 | H11: 2026 | I11: 2026 | J11: 2026 | K11: 2026 | L11: 2026 | M11: 2026 | N11: 2026 | O11: 2026 | P11: 2026 | Q11: 2026 | R11: 2026 | S11: 2026 | T11: 2027 | U11: 2027 | V11: 2027 | W11: 2027 | X11: 2027 | Y11: 2027 | Z11: 2027 | AA11: 2027 | AB11: 2027 | AC11: 2027 | AD11: 2027 | AE11: 2027 | AF11: 2028 | AG11: 2028 | AH11: 2028 | AI11: 2028 | AJ11: 2028 | AK11: 2028 | AL11: 2028 | AM11: 2028 | AN11: 2028 | AO11: 2028 | AP11: 2028 | AQ11: 2028 | AR11: 2029 | AS11: 2029 | AT11: 2029 | AU11: 2029 | AV11: 2029 | AW11: 2029 | AX11: 2029 | AY11: 2029 | AZ11: 2029 | BA11: 2029 | BB11: 2029 | BC11: 2029 | BD11: 2030 | BE11: 2030 | BF11: 2030 | BG11: 2030 | BH11: 2030 | BI11: 2030 | BJ11: 2030 | BK11: 2030 | BL11: 2030 | BM11: 2030 | BN11: 2030 | BO11: 2030
B14: 1 P&L Statement
C16: Net Revenue
C17: {=C309:C311} -> Device Sales | F17: [$k] | H17: {=H309:BO311} -> 80025.397 | I17: 75097.91 | J17: 100109.65 | K17: 100214.14 | L17: 100288.92 | M17: 100303.62 | N17: 100401.92 | O17: 100502.63 | P17: 100600.43 | Q17: 100738.26 | R17: 100842.18 | S17: 151408.85 | T17: 83225.257 | U17: 78098.892 | V17: 104236.65 | W17: 104329.58 | X17: 104434.02 | Y17: 104537.09 | Z17: 104637.43 | AA17: 104735.96 | AB17: 104796.68 | AC17: 104900.18 | AD17: 105001.36 | AE17: 157502.04 | AF17: 86592.598 | AG17: 81242.19 | AH17: 108455.14 | AI17: 108559.96 | AJ17: 108648.65 | AK17: 108759.51 | AL17: 108838.85 | AM17: 108901.21 | AN17: 109005.5 | AO17: 109112.34 | AP17: 109216.09 | AQ17: 164043.47 | AR17: 90205.398 | AS17: 84647.095 | AT17: 112953.55 | AU17: 113059.95 | AV17: 113171.12 | AW17: 113171.12 | AX17: 113281.91 | AY17: 113391.27 | AZ17: 113497.71 | BA17: 113602.24 | BB17: 113688.14 | BC17: 170696.91 | BD17: 93857.952 | BE17: 88081.419 | BF17: 117536.68 | BG17: 117623.86 | BH17: 117764.13 | BI17: 117875.33 | BJ17: 117969.43 | BK17: 118087.04 | BL17: 118171.21 | BM17: 118237.36 | BN17: 118348.01 | BO17: 177692.04
C18: Accessory Sales | F18: [$k] | H18: 12109.641 | I18: 11363.604 | J18: 15148.382 | K18: 15163.223 | L18: 15175.926 | M18: 15177.986 | N18: 15192.818 | O18: 15208.027 | P18: 15222.265 | Q18: 15244.152 | R18: 15262.006 | S18: 22917.419 | T18: 12594.904 | U18: 11818.521 | V18: 15774.815 | W18: 15788.253 | X18: 15804.962 | Y18: 15820.836 | Z18: 15835.619 | AA18: 15850.453 | AB18: 15857.455 | AC18: 15873.654 | AD18: 15888.658 | AE18: 23832.987 | AF18: 13103.618 | AG18: 12291.199 | AH18: 16408.116 | AI18: 16423.414 | AJ18: 16436.527 | AK18: 16452.272 | AL18: 16465.749 | AM18: 16474.491 | AN18: 16490.226 | AO18: 16506.361 | AP18: 16521.466 | AQ18: 24817.03 | AR18: 13648.429 | AS18: 12808.739 | AT18: 17088.223 | AU18: 17103.498 | AV18: 17121.308 | AW18: 17121.308 | AX18: 17139.034 | AY18: 17155.875 | AZ18: 17171.558 | BA18: 17187.295 | BB18: 17197.199 | BC18: 25821.578 | BD18: 14197.77 | BE18: 13325.538 | BF18: 17782.454 | BG18: 17791.728 | BH18: 17812.788 | BI18: 17829.018 | BJ18: 17842.929 | BK18: 17859.634 | BL18: 17873.931 | BM18: 17883.205 | BN18: 17899.899 | BO18: 26875.524
C19: Mobile Plan commissions | F19: [$k] | H19: 5331.8293 | I19: 5003.704 | J19: 6670.2086 | K19: 6677.0581 | L19: 6682.2768 | M19: 6683.2518 | N19: 6689.725 | O19: 6696.3428 | P19: 6703.1469 | Q19: 6710.8719 | R19: 6717.7385 | S19: 10087.546 | T19: 5546.365 | U19: 5204.389 | V19: 6946.1103 | W19: 6951.6977 | X19: 6958.7659 | Y19: 6965.7372 | Z19: 6972.4222 | AA19: 6979.2563 | AB19: 6984.9215 | AC19: 6992.1519 | AD19: 6998.5325 | AE19: 10497.799 | AF19: 5771.3657 | AG19: 5416.1463 | AH19: 7229.5781 | AI19: 7236.8119 | AJ19: 7242.7389 | AK19: 7250.0055 | AL19: 7255.542 | AM19: 7259.6798 | AN19: 7266.5472 | AO19: 7273.568 | AP19: 7280.7865 | AQ19: 10933.473 | AR19: 6012.1238 | AS19: 5642.3425 | AT19: 7531.8573 | AU19: 7538.4657 | AV19: 7545.8124 | AW19: 7545.8124 | AX19: 7553.3111 | AY19: 7560.7069 | AZ19: 7567.799 | BA19: 7575.0493 | BB19: 7583.0629 | BC19: 11386.101 | BD19: 6260.3423 | BE19: 5874.5311 | BF19: 7838.775 | BG19: 7846.5422 | BH19: 7855.0821 | BI19: 7862.7565 | BJ19: 7869.0444 | BK19: 7876.7536 | BL19: 7882.6273 | BM19: 7887.017 | BN19: 7894.3026 | BO19: 11852.627
C20: Total Net Revenue | F20: [$k] | H20: =SUM(H17:H19) -> 97466.867 | I20: =SUM(I17:I19) -> 91465.218 | J20: =SUM(J17:J19) -> 121928.24 | K20: =SUM(K17:K19) -> 122054.43 | L20: =SUM(L17:L19) -> 122147.13 | M20: =SUM(M17:M19) -> 122164.86 | N20: =SUM(N17:N19) -> 122284.47 | O20: =SUM(O17:O19) -> 122407 | ... BO20: =SUM(BO17:BO19) -> 216420.19
C22: COGS (Cost of Goods Sold)
C23: {=C321:C322} -> Device Sales | F23: [$k] | H23: {=-H321:BO322} -> -72022.857 | I23: -67588.119 | J23: -90098.682 | K23: -90192.73 | L23: -90260.03 | M23: -90273.255 | N23: -90361.731 | O23: -90452.371 | P23: -90540.387 | Q23: -90664.431 | R23: -90757.966 | S23: -136267.96 | T23: -74902.731 | U23: -70289.003 | V23: -93812.983 | W23: -93896.625 | X23: -93990.614 | Y23: -94083.382 | Z23: -94173.686 | AA23: -94262.362 | AB23: -94317.015 | AC23: -94410.16 | AD23: -94501.222 | AE23: -141751.83 | AF23: -77933.338 | AG23: -73117.971 | AH23: -97609.626 | AI23: -97703.962 | AJ23: -97783.787 | AK23: -97883.563 | AL23: -97954.962 | AM23: -98011.085 | AN23: -98104.949 | AO23: -98201.109 | AP23: -98294.485 | AQ23: -147639.12 | AR23: -81184.858 | AS23: -76182.385 | AT23: -101658.2 | AU23: -101753.95 | AV23: -101854.01 | AW23: -101854.01 | AX23: -101953.72 | AY23: -102052.14 | AZ23: -102147.94 | BA23: -102242.02 | BB23: -102319.33 | BC23: -153627.22 | BD23: -84472.157 | BE23: -79273.277 | BF23: -105783.01 | BG23: -105861.47 | BH23: -105987.72 | BI23: -106087.8 | BJ23: -106172.49 | BK23: -106278.34 | BL23: -106354.08 | BM23: -106413.63 | BN23: -106513.21 | BO23: -159922.83
C24: Accessory Sales | F24: [$k] | H24: -3632.8924 | I24: -3409.0811 | J24: -4544.5145 | K24: -4548.9669 | L24: -4552.7779 | M24: -4553.3959 | N24: -4557.8455 | O24: -4562.408 | P24: -4566.6794 | Q24: -4573.2457 | R24: -4578.6017 | S24: -6875.2258 | T24: -3778.4712 | U24: -3545.5563 | V24: -4732.4445 | W24: -4736.476 | X24: -4741.4887 | Y24: -4746.2508 | Z24: -4750.6858 | AA24: -4755.1358 | AB24: -4757.2364 | AC24: -4762.0961 | AD24: -4766.5973 | AE24: -7149.896 | AF24: -3931.0855 | AG24: -3687.3596 | AH24: -4922.4348 | AI24: -4927.0243 | AJ24: -4930.9581 | AK24: -4935.6816 | AL24: -4939.7247 | AM24: -4942.3473 | AN24: -4947.0679 | AO24: -4951.9082 | AP24: -4956.4398 | AQ24: -7445.1089 | AR24: -4094.5286 | AS24: -3842.6217 | AT24: -5126.467 | AU24: -5131.0494 | AV24: -5136.3923 | AW24: -5136.3923 | AX24: -5141.7103 | AY24: -5146.7625 | AZ24: -5151.4675 | BA24: -5156.1885 | BB24: -5159.1598 | BC24: -7746.4733 | BD24: -4259.3309 | BE24: -3997.6613 | BF24: -5334.7362 | BG24: -5337.5185 | BH24: -5343.8365 | BI24: -5348.7055 | BJ24: -5352.8788 | BK24: -5357.8901 | BL24: -5362.1794 | BM24: -5364.9616 | BN24: -5369.9697 | BO24: -8062.6572
C25: Mobile Plans | F25: [$k] | H25: 0 | I25: 0 | J25: 0 | K25: 0 | L25: 0 | M25: 0 | N25: 0 | O25: 0 | P25: 0 | Q25: 0 | R25: 0 | S25: 0 | T25: 0 | U25: 0 | V25: 0 | W25: 0 | X25: 0 | Y25: 0 | Z25: 0 | AA25: 0 | AB25: 0 | AC25: 0 | AD25: 0 | AE25: 0 | AF25: 0 | AG25: 0 | AH25: 0 | AI25: 0 | AJ25: 0 | AK25: 0 | AL25: 0 | AM25: 0 | AN25: 0 | AO25: 0 | AP25: 0 | AQ25: 0 | AR25: 0 | AS25: 0 | AT25: 0 | AU25: 0 | AV25: 0 | AW25: 0 | AX25: 0 | AY25: 0 | AZ25: 0 | BA25: 0 | BB25: 0 | BC25: 0 | BD25: 0 | BE25: 0 | BF25: 0 | BG25: 0 | BH25: 0 | BI25: 0 | BJ25: 0 | BK25: 0 | BL25: 0 | BM25: 0 | BN25: 0 | BO25: 0
C26: Total COGS | F26: [$k] | H26: =SUM(H23:H25) -> -75655.75 | I26: =SUM(I23:I25) -> -70997.2 | J26: =SUM(J23:J25) -> -94643.196 | K26: =SUM(K23:K25) -> -94741.697 | L26: =SUM(L23:L25) -> -94812.808 | M26: =SUM(M23:M25) -> -94826.651 | N26: =SUM(N23:N25) -> -94919.577 | O26: =SUM(O23:O25) -> -95014.779 | ... BO26: =SUM(BO23:BO25) -> -167985.49
C28: Gross Profit | H28: {=H20:BO20+H26:BO26} -> 21811.118 | I28: 20468.018 | J28: 27285.04 | K28: 27312.729 | L28: 27334.317 | M28: 27338.204 | N28: 27364.89 | O28: 27392.225 | P28: 27418.775 | Q28: 27455.604 | R28: 27485.361 | S28: 41270.625 | T28: 22685.323 | U28: 21287.243 | V28: 28412.146 | W28: 28436.433 | X28: 28465.641 | Y28: 28494.032 | Z28: 28521.099 | AA28: 28548.169 | AB28: 28564.808 | AC28: 28593.727 | AD28: 28620.729 | AE28: 42931.093 | AF28: 23603.158 | AG28: 22144.204 | AH28: 29560.773 | AI28: 29589.198 | AJ28: 29613.173 | AK28: 29642.547 | AL28: 29665.451 | AM28: 29681.944 | AN28: 29710.255 | AO28: 29739.255 | AP28: 29767.422 | AQ28: 44709.741 | AR28: 24586.564 | AS28: 23073.169 | AT28: 30788.969 | AU28: 30816.909 | AV28: 30847.84 | AW28: 30847.84 | AX28: 30878.826 | AY28: 30908.946 | AZ28: 30937.661 | BA28: 30966.38 | BB28: 30989.917 | BC28: 46530.896 | BD28: 25584.576 | BE28: 24010.549 | BF28: 32040.161 | BG28: 32063.138 | BH28: 32100.447 | BI28: 32130.603 | BJ28: 32156.038 | BK28: 32187.201 | BL28: 32211.5 | BM28: 32228.997 | BN28: 32259.033 | BO28: 48434.697
C30: Sales Expense
C31: {=C432:C434} -> Payroll | F31: [$k] | H31: {=-H432:BO434} -> -8768.184 | I31: -8775.6 | J31: -8783.016 | K31: -8790.432 | L31: -8797.848 | M31: -8805.264 | N31: -8812.68 | O31: -8820.096 | P31: -8827.512 | Q31: -8834.928 | R31: -8842.344 | S31: -8849.76 | T31: -9122.8913 | U31: -9130.5298 | V31: -9138.1682 | W31: -9145.8067 | X31: -9153.4452 | Y31: -9161.0837 | Z31: -9168.7222 | AA31: -9176.3606 | AB31: -9183.9991 | AC31: -9191.6376 | AD31: -9199.2761 | AE31: -9206.9146 | AF31: -9490.9896 | AG31: -9498.8573 | AH31: -9506.7249 | AI31: -9514.5925 | AJ31: -9522.4602 | AK31: -9530.3278 | AL31: -9538.1954 | AM31: -9546.0631 | AN31: -9553.9307 | AO31: -9561.7983 | AP31: -9569.666 | AQ31: -9577.5336 | AR31: -9872.9633 | AS31: -9881.0669 | AT31: -9889.1706 | AU31: -9897.2743 | AV31: -9905.3779 | AW31: -9913.4816 | AX31: -9921.5853 | AY31: -9929.6889 | AZ31: -9937.7926 | BA31: -9945.8963 | BB31: -9953.9999 | BC31: -9962.1036 | BD31: -10269.313 | BE31: -10277.66 | BF31: -10286.007 | BG31: -10294.354 | BH31: -10302.701 | BI31: -10311.047 | BJ31: -10319.394 | BK31: -10327.741 | BL31: -10336.088 | BM31: -10344.434 | BN31: -10352.781 | BO31: -10361.128
C32: Rent & Utilities | F32: [$k] | H32: -3008.2791 | I32: -3011.1853 | J32: -3014.3989 | K32: -3017.6514 | L32: -3019.7682 | M32: -3021.542 | N32: -3024.5455 | O32: -3027.5741 | P32: -3030.5039 | Q32: -3035.0159 | R32: -3038.3215 | S32: -3041.2906 | T32: -3135.8017 | U32: -3139.1254 | V32: -3142.3219 | W32: -3145.8543 | X32: -3148.6403 | Y32: -3151.7102 | Z32: -3154.7241 | AA32: -3157.6672 | AB32: -3160.6833 | AC32: -3163.8435 | AD32: -3166.5914 | AE32: -3170.5317 | AF32: -3268.4905 | AG32: -3270.1422 | AH32: -3274.0313 | AI32: -3277.1145 | AJ32: -3280.5239 | AK32: -3283.9744 | AL32: -3286.2201 | AM32: -3288.102 | AN32: -3291.2884 | AO32: -3294.5014 | AP32: -3297.6096 | AQ32: -3302.3964 | AR32: -3405.0805 | AS32: -3408.3249 | AT32: -3411.7965 | AU32: -3415.3226 | AV32: -3418.7138 | AW32: -3422.4613 | AX32: -3425.4169 | AY32: -3428.6738 | AZ32: -3431.8713 | BA32: -3434.9936 | BB32: -3438.1933 | BC32: -3441.5461 | BD32: -3547.7952 | BE32: -3552.1008 | BF32: -3555.1168 | BG32: -3556.869 | BH32: -3560.995 | BI32: -3564.266 | BJ32: -3567.883 | BK32: -3571.5436 | BL32: -3573.9261 | BM32: -3575.9226 | BN32: -3579.3031 | BO32: -3582.7118
C33: Other Sales Expenses | F33: [$k] | H33: -1031.03 | I33: -1032.06 | J33: -1033.09 | K33: -1034.12 | L33: -1035.15 | M33: -1036.18 | N33: -1037.21 | O33: -1038.24 | P33: -1039.27 | Q33: -1040.3 | R33: -1041.33 | S33: -1042.36 | T33: -1074.6917 | U33: -1075.7526 | V33: -1076.8135 | W33: -1077.8744 | X33: -1078.9353 | Y33: -1079.9962 | Z33: -1081.0571 | AA33: -1082.118 | AB33: -1083.1789 | AC33: -1084.2398 | AD33: -1085.3007 | AE33: -1086.3616 | AF33: -1120.0452 | AG33: -1121.1379 | AH33: -1122.2306 | AI33: -1123.3234 | AJ33: -1124.4161 | AK33: -1125.5088 | AL33: -1126.6015 | AM33: -1127.6943 | AN33: -1128.787 | AO33: -1129.8797 | AP33: -1130.9724 | AQ33: -1132.0652 | AR33: -1167.1526 | AS33: -1168.2781 | AT33: -1169.4037 | AU33: -1170.5292 | AV33: -1171.6547 | AW33: -1172.7802 | AX33: -1173.9057 | AY33: -1175.0312 | AZ33: -1176.1567 | BA33: -1177.2822 | BB33: -1178.4077 | BC33: -1179.5332 | BD33: -1216.0785 | BE33: -1217.2378 | BF33: -1218.3971 | BG33: -1219.5563 | BH33: -1220.7156 | BI33: -1221.8749 | BJ33: -1223.0341 | BK33: -1224.1934 | BL33: -1225.3527 | BM33: -1226.512 | BN33: -1227.6712 | BO33: -1228.8305
C34: Total Sales Expense | F34: [$k] | H34: =SUM(H31:H33) -> -12807.493 | I34: =SUM(I31:I33) -> -12818.845 | J34: =SUM(J31:J33) -> -12830.505 | K34: =SUM(K31:K33) -> -12842.203 | L34: =SUM(L31:L33) -> -12852.766 | M34: =SUM(M31:M33) -> -12862.986 | N34: =SUM(N31:N33) -> -12874.436 | O34: =SUM(O31:O33) -> -12885.91 | ... BO34: =SUM(BO31:BO33) -> -15172.67
C36: General & Administrative Expenses | F36: [$k] | H36: {=-H435:BO435} -> -5152.06 | I36: -5154.12 | J36: -5156.18 | K36: -5158.24 | L36: -5160.3 | M36: -5162.36 | N36: -5164.42 | O36: -5166.48 | P36: -5168.54 | Q36: -5170.6 | R36: -5172.66 | S36: -5174.72 | T36: -5332.0834 | U36: -5334.2052 | V36: -5336.327 | W36: -5338.4488 | X36: -5340.5706 | Y36: -5342.6924 | Z36: -5344.8142 | AA36: -5346.936 | AB36: -5349.0578 | AC36: -5351.1796 | AD36: -5353.3014 | AE36: -5355.4232 | AF36: -5518.2713 | AG36: -5520.4568 | AH36: -5522.6423 | AI36: -5524.8277 | AJ36: -5527.0132 | AK36: -5529.1986 | AL36: -5531.3841 | AM36: -5533.5695 | AN36: -5535.755 | AO36: -5537.9404 | AP36: -5540.1259 | AQ36: -5542.3113 | AR36: -5710.8317 | AS36: -5713.0827 | AT36: -5715.3337 | AU36: -5717.5848 | AV36: -5719.8358 | AW36: -5722.0868 | AX36: -5724.3378 | AY36: -5726.5888 | AZ36: -5728.8398 | BA36: -5731.0909 | BB36: -5733.3419 | BC36: -5735.5929 | BD36: -5909.9792 | BE36: -5912.2978 | BF36: -5914.6163 | BG36: -5916.9349 | BH36: -5919.2534 | BI36: -5921.572 | BJ36: -5923.8905 | BK36: -5926.2091 | BL36: -5928.5276 | BM36: -5930.8462 | BN36: -5933.1647 | BO36: -5935.4833
C38: EBITDA | H38: {=_xlfn.ANCHORARRAY(H28)+H34:BO34+_xlfn.ANCHORARRAY(H36)} -> 3851.5649 | I38: 2495.0523 | J38: 9298.3554 | K38: 9312.2853 | L38: 9321.2513 | M38: 9312.858 | N38: 9326.0346 | O38: 9339.8347 | P38: 9352.9494 | Q38: 9374.7603 | R38: 9390.7054 | S38: 23162.494 | T38: 4019.8554 | U38: 2607.6299 | V38: 9718.515 | W38: 9728.449 | X38: 9744.0497 | Y38: 9758.5491 | Z38: 9771.7809 | AA38: 9785.087 | AB38: 9787.8889 | AC38: 9802.8268 | AD38: 9816.2591 | AE38: 24111.862 | AF38: 4205.3617 | AG38: 2733.6102 | AH38: 10135.144 | AI38: 10149.34 | AJ38: 10158.76 | AK38: 10173.538 | AL38: 10183.05 | AM38: 10186.515 | AN38: 10200.494 | AO38: 10215.135 | AP38: 10229.048 | AQ38: 25155.434 | AR38: 4430.5356 | AS38: 2902.4167 | AT38: 10603.265 | AU38: 10616.198 | AV38: 10632.258 | AW38: 10617.03 | AX38: 10633.581 | AY38: 10648.963 | AZ38: 10663.001 | BA38: 10677.117 | BB38: 10685.974 | BC38: 26212.12 | BD38: 4641.4099 | BE38: 3051.2527 | BF38: 11066.024 | BG38: 11075.424 | BH38: 11096.783 | BI38: 11111.842 | BJ38: 11121.836 | BK38: 11137.514 | BL38: 11147.606 | BM38: 11151.282 | BN38: 11166.112 | BO38: 27326.543
C39: EBITDA MARGIN | H39: =H38/H20 -> 0.039516658 | I39: =I38/I20 -> 0.027278701 | J39: =J38/J20 -> 0.076260887 | K39: =K38/K20 -> 0.076296171 | L39: =L38/L20 -> 0.076311671 | M39: =M38/M20 -> 0.076231891 | N39: =N38/N20 -> 0.07626508 | O39: =O38/O20 -> 0.076301473 | ... BO39: =BO38/BO20 -> 0.12626615 | BR39: =BR38/BR20 -> #DIV/0! | BS39: =BS38/BS20 -> #DIV/0! | BT39: =BT38/BT20 -> #DIV/0! | BU39: =BU38/BU20 -> #DIV/0! | BV39: =BV38/BV20 -> #DIV/0! | BW39: =BW38/BW20 -> #DIV/0! | BX39: =BX38/BX20 -> #DIV/0! | BY39: =BY38/BY20 -> #DIV/0! | ... CF39: =CF38/CF20 -> #DIV/0!
C41: Depriciation | F41: [$k] | H41: {=_xlfn.ANCHORARRAY(H472)} -> -2777.7778 | I41: -2779.4944 | J41: -2781.2111 | K41: -2782.9278 | L41: -2784.6444 | M41: -2786.3611 | N41: -2788.0778 | O41: -2789.7944 | P41: -2791.5111 | Q41: -2793.2278 | R41: -2794.9444 | S41: -2796.6611 | T41: -2798.3778 | U41: -2800.1459 | V41: -2801.9141 | W41: -2803.6823 | X41: -2805.4504 | Y41: -2807.2186 | Z41: -2808.9868 | AA41: -2810.7549 | AB41: -2812.5231 | AC41: -2814.2913 | AD41: -2816.0594 | AE41: -2817.8276 | AF41: -2819.5958 | AG41: -2821.417 | AH41: -2823.2382 | AI41: -2825.0594 | AJ41: -2826.8806 | AK41: -2828.7018 | AL41: -2830.523 | AM41: -2832.3443 | AN41: -2834.1655 | AO41: -2835.9867 | AP41: -2837.8079 | AQ41: -2839.6291 | AR41: -63.67254 | AS41: -65.548388 | AT41: -67.424236 | AU41: -69.300084 | AV41: -71.175932 | AW41: -73.05178 | AX41: -74.927628 | AY41: -76.803476 | AZ41: -78.679324 | BA41: -80.555172 | BB41: -82.43102 | BC41: -84.306868 | BD41: -86.182716 | BE41: -88.11484 | BF41: -90.046963 | BG41: -91.979087 | BH41: -93.91121 | BI41: -95.843333 | BJ41: -97.775457 | BK41: -99.70758 | BL41: -101.6397 | BM41: -103.57183 | BN41: -105.50395 | BO41: -107.43607
C42: Amortization | F42: [$k] | H42: {=H478:BO478} -> -27.777778 | I42: -27.777778 | J42: -27.777778 | K42: -27.777778 | L42: -27.777778 | M42: -27.777778 | N42: -27.777778 | O42: -27.777778 | P42: -27.777778 | Q42: -27.777778 | R42: -27.777778 | S42: -27.777778 | T42: -27.777778 | U42: -27.777778 | V42: -27.777778 | W42: -27.777778 | X42: -27.777778 | Y42: -27.777778 | Z42: -27.777778 | AA42: -27.777778 | AB42: -27.777778 | AC42: -27.777778 | AD42: -27.777778 | AE42: -27.777778 | AF42: -27.777778 | AG42: -27.777778 | AH42: -27.777778 | AI42: -27.777778 | AJ42: -27.777778 | AK42: -27.777778 | AL42: -27.777778 | AM42: -27.777778 | AN42: -27.777778 | AO42: -27.777778 | AP42: -27.777778 | AQ42: -27.777778 | AR42: -27.777778 | AS42: -27.777778 | AT42: -27.777778 | AU42: -27.777778 | AV42: -27.777778 | AW42: -27.777778 | AX42: -27.777778 | AY42: -27.777778 | AZ42: -27.777778 | BA42: -27.777778 | BB42: -27.777778 | BC42: -27.777778 | BD42: -27.777778 | BE42: -27.777778 | BF42: -27.777778 | BG42: -27.777778 | BH42: -27.777778 | BI42: -27.777778 | BJ42: -27.777778 | BK42: -27.777778 | BL42: -27.777778 | BM42: -27.777778 | BN42: -27.777778 | BO42: -27.777778
C44: EBIT | H44: {=_xlfn.ANCHORARRAY(H38)+_xlfn.ANCHORARRAY(H41)+_xlfn.ANCHORARRAY(H42)} -> 1046.0093 | I44: -312.2199 | J44: 6489.3665 | K44: 6501.5797 | L44: 6508.829 | M44: 6498.7191 | N44: 6510.1791 | O44: 6522.2625 | P44: 6533.6605 | Q44: 6553.7547 | R44: 6567.9831 | S44: 20338.055 | T44: 1193.6999 | U44: -220.29382 | V44: 6888.8231 | W44: 6896.9889 | X44: 6910.8215 | Y44: 6923.5527 | Z44: 6935.0164 | AA44: 6946.5543 | AB44: 6947.588 | AC44: 6960.7577 | AD44: 6972.4219 | AE44: 21266.257 | AF44: 1357.9881 | AG44: -115.58461 | AH44: 7284.1283 | AI44: 7296.5024 | AJ44: 7304.1013 | AK44: 7317.0583 | AL44: 7324.7491 | AM44: 7326.3931 | AN44: 7338.551 | AO44: 7351.3703 | AP44: 7363.4624 | AQ44: 22288.027 | AR44: 4339.0853 | AS44: 2809.0905 | AT44: 10508.063 | AU44: 10519.12 | AV44: 10533.304 | AW44: 10516.2 | AX44: 10530.875 | AY44: 10544.382 | AZ44: 10556.544 | BA44: 10568.784 | BB44: 10575.765 | BC44: 26100.035 | BD44: 4527.4494 | BE44: 2935.3601 | BF44: 10948.199 | BG44: 10955.667 | BH44: 10975.094 | BI44: 10988.221 | BJ44: 10996.283 | BK44: 11010.029 | BL44: 11018.188 | BM44: 11019.932 | BN44: 11032.831 | BO44: 27191.33
C46: Interest | H46: {=H513:BO513} -> -309.58333 | I46: -356.49122 | J46: -354.99798 | K46: -298.01042 | L46: -294.15278 | M46: -290.29514 | N46: -286.4375 | O46: -282.57986 | P46: -278.72222 | Q46: -274.86458 | R46: -271.00694 | S46: -267.14931 | T46: -257.29167 | U46: -253.55903 | V46: -249.82639 | W46: -246.09375 | X46: -242.36111 | Y46: -238.62847 | Z46: -234.89583 | AA46: -231.16319 | AB46: -227.43056 | AC46: -223.69792 | AD46: -219.96528 | AE46: -216.23264 | AF46: -208.75 | AG46: -205.12153 | AH46: -201.49306 | AI46: -197.86458 | AJ46: -194.23611 | AK46: -190.60764 | AL46: -186.97917 | AM46: -183.35069 | AN46: -179.72222 | AO46: -176.09375 | AP46: -172.46528 | AQ46: -168.83681 | AR46: -165.20833 | AS46: -161.57986 | AT46: -157.95139 | AU46: -154.32292 | AV46: -150.69444 | AW46: -147.06597 | AX46: -143.4375 | AY46: -139.80903 | AZ46: -136.18056 | BA46: -132.55208 | BB46: -128.92361 | BC46: -125.29514 | BD46: -121.66667 | BE46: -118.03819 | BF46: -114.40972 | BG46: -110.78125 | BH46: -107.15278 | BI46: -103.52431 | BJ46: -99.895833 | BK46: -96.267361 | BL46: -92.638889 | BM46: -89.010417 | BN46: -85.381944 | BO46: -81.753472
C48: Earnings before Tax | H48: {=_xlfn.ANCHORARRAY(H44)+_xlfn.ANCHORARRAY(H46)} -> 736.42598 | I48: -668.71111 | J48: 6134.3686 | K48: 6203.5693 | L48: 6214.6763 | M48: 6208.4239 | N48: 6223.7416 | O48: 6239.6827 | P48: 6254.9383 | Q48: 6278.8902 | R48: 6296.9762 | S48: 20070.906 | T48: 936.4082 | U48: -473.85285 | V48: 6638.9967 | W48: 6650.8952 | X48: 6668.4604 | Y48: 6684.9243 | Z48: 6700.1205 | AA48: 6715.3911 | AB48: 6720.1575 | AC48: 6737.0598 | AD48: 6752.4566 | AE48: 21050.024 | AF48: 1149.2381 | AG48: -320.70614 | AH48: 7082.6352 | AI48: 7098.6378 | AJ48: 7109.8652 | AK48: 7126.4506 | AL48: 7137.7699 | AM48: 7143.0424 | AN48: 7158.8288 | AO48: 7175.2766 | AP48: 7190.9971 | AQ48: 22119.191 | AR48: 4173.877 | AS48: 2647.5107 | AT48: 10350.111 | AU48: 10364.797 | AV48: 10382.609 | AW48: 10369.134 | AX48: 10387.438 | AY48: 10404.573 | AZ48: 10420.363 | BA48: 10436.232 | BB48: 10446.841 | BC48: 25974.74 | BD48: 4405.7827 | BE48: 2817.3219 | BF48: 10833.789 | BG48: 10844.886 | BH48: 10867.941 | BI48: 10884.697 | BJ48: 10896.387 | BK48: 10913.762 | BL48: 10925.549 | BM48: 10930.922 | BN48: 10947.449 | BO48: 27109.576
C50: Corporate Income Tax | D50: =Assumptions!D61 -> 0.2 | H50: {=-_xlfn.ANCHORARRAY(H48)*D50} -> -147.2852 | I50: 133.74222 | J50: -1226.8737 | K50: -1240.7139 | L50: -1242.9353 | M50: -1241.6848 | N50: -1244.7483 | O50: -1247.9365 | P50: -1250.9877 | Q50: -1255.778 | R50: -1259.3952 | S50: -4014.1812 | T50: -187.28164 | U50: 94.77057 | V50: -1327.7993 | W50: -1330.179 | X50: -1333.6921 | Y50: -1336.9849 | Z50: -1340.0241 | AA50: -1343.0782 | AB50: -1344.0315 | AC50: -1347.412 | AD50: -1350.4913 | AE50: -4210.0048 | AF50: -229.84762 | AG50: 64.141228 | AH50: -1416.527 | AI50: -1419.7276 | AJ50: -1421.973 | AK50: -1425.2901 | AL50: -1427.554 | AM50: -1428.6085 | AN50: -1431.7658 | AO50: -1435.0553 | AP50: -1438.1994 | AQ50: -4423.8381 | AR50: -834.77539 | AS50: -529.50214 | AT50: -2070.0222 | AU50: -2072.9595 | AV50: -2076.5219 | AW50: -2073.8269 | AX50: -2077.4876 | AY50: -2080.9146 | AZ50: -2084.0726 | BA50: -2087.2464 | BB50: -2089.3683 | BC50: -5194.9481 | BD50: -881.15655 | BE50: -563.46438 | BF50: -2166.7579 | BG50: -2168.9771 | BH50: -2173.5881 | BI50: -2176.9394 | BJ50: -2179.2774 | BK50: -2182.7523 | BL50: -2185.1098 | BM50: -2186.1844 | BN50: -2189.4897 | BO50: -5421.9152
C52: Net Income | H52: {=_xlfn.ANCHORARRAY(H48)+_xlfn.ANCHORARRAY(H50)} -> 589.14079 | I52: -534.96889 | J52: 4907.4949 | K52: 4962.8554 | L52: 4971.741 | M52: 4966.7391 | N52: 4978.9933 | O52: 4991.7461 | P52: 5003.9506 | Q52: 5023.1121 | R52: 5037.581 | S52: 16056.725 | T52: 749.12656 | U52: -379.08228 | V52: 5311.1974 | W52: 5320.7161 | X52: 5334.7683 | Y52: 5347.9394 | Z52: 5360.0964 | AA52: 5372.3129 | AB52: 5376.126 | AC52: 5389.6479 | AD52: 5401.9653 | AE52: 16840.019 | AF52: 919.39048 | AG52: -256.56491 | AH52: 5666.1082 | AI52: 5678.9103 | AJ52: 5687.8922 | AK52: 5701.1605 | AL52: 5710.2159 | AM52: 5714.4339 | AN52: 5727.063 | AO52: 5740.2213 | AP52: 5752.7977 | AQ52: 17695.352 | AR52: 3339.1016 | AS52: 2118.0085 | AT52: 8280.0889 | AU52: 8291.838 | AV52: 8306.0875 | AW52: 8295.3075 | AX52: 8309.9503 | AY52: 8323.6583 | AZ52: 8336.2905 | BA52: 8348.9857 | BB52: 8357.4732 | BC52: 20779.792 | BD52: 3524.6262 | BE52: 2253.8575 | BF52: 8667.0315 | BG52: 8675.9085 | BH52: 8694.3526 | BI52: 8707.7576 | BJ52: 8717.1097 | BK52: 8731.0093 | BL52: 8740.4394 | BM52: 8744.7375 | BN52: 8757.9589 | BO52: 21687.661
B54: 2 Balance Sheet
C56: Current Assets
C57: Cash | F57: [$k] | G57: =Assumptions!D47 -> 10000 | H57: {=H112:BO112} -> 0 | I57: 0 | J57: 6112.9616 | K57: 10498.991 | L57: 14867.781 | M57: 19212.189 | N57: 23598.125 | O57: 27993.119 | P57: 32394.63 | Q57: 36824.783 | R57: 41249.183 | S57: 70911.815 | T57: 44037.024 | U57: 43708.161 | V57: 58447.966 | W57: 63013.153 | X57: 67590.726 | Y57: 72176.39 | Z57: 76768.856 | AA57: 81368.335 | AB57: 85956.49 | AC57: 90570.231 | AD57: 95190.924 | AE57: 126017.53 | AF57: 98072.485 | AG57: 97730.953 | AH57: 113084.62 | AI57: 117848.41 | AJ57: 122612.53 | AK57: 127393.88 | AL57: 132168.03 | AM57: 136939.39 | AN57: 141736.31 | AO57: 146542.65 | AP57: 151355.72 | AQ57: 183536.69 | AR57: 153340.54 | AS57: 151344.33 | AT57: 165669.49 | AU57: 168979.13 | AV57: 172299.3 | AW57: 175572.83 | AX57: 178898.13 | AY57: 182231.89 | AZ57: 185572.73 | BA57: 188920.88 | BB57: 192267.5 | BC57: 224079.51 | BD57: 192151.24 | BE57: 190155.25 | BF57: 205139.33 | BG57: 208647.98 | BH57: 212191.04 | BI57: 215730.39 | BJ57: 219269.99 | BK57: 222827.8 | BL57: 226377.88 | BM57: 229924.91 | BN57: 233498.96 | BO57: 266695
C58: Accounts Receiveable | F58: [$k] | G58: =Assumptions!D48 -> 90000 | H58: {=_xlfn.ANCHORARRAY(H448)} -> 48733.434 | I58: 45732.609 | J58: 60964.118 | K58: 61027.213 | L58: 61073.563 | M58: 61082.428 | N58: 61142.233 | O58: 61203.502 | P58: 61262.921 | Q58: 61346.641 | R58: 61410.964 | S58: 92206.906 | T58: 50683.263 | U58: 47560.901 | V58: 63478.787 | W58: 63534.767 | X58: 63598.872 | Y58: 63661.832 | Z58: 63722.735 | AA58: 63782.833 | AB58: 63819.53 | AC58: 63882.992 | AD58: 63944.274 | AE58: 95916.411 | AF58: 52733.791 | AG58: 49474.768 | AH58: 66046.417 | AI58: 66110.092 | AJ58: 66163.959 | AK58: 66230.896 | AL58: 66280.069 | AM58: 66317.688 | AN58: 66381.136 | AO58: 66446.136 | AP58: 66509.173 | AQ58: 99896.987 | AR58: 54932.975 | AS58: 51549.088 | AT58: 68786.817 | AU58: 68850.955 | AV58: 68919.12 | AW58: 68919.12 | AX58: 68987.129 | AY58: 69053.924 | AZ58: 69118.536 | BA58: 69182.294 | BB58: 69234.202 | BC58: 103952.29 | BD58: 57158.032 | BE58: 53640.744 | BF58: 71578.955 | BG58: 71631.065 | BH58: 71716.001 | BI58: 71783.554 | BJ58: 71840.701 | BK58: 71911.715 | BL58: 71963.882 | BM58: 72003.792 | BN58: 72071.104 | BO58: 108210.09
C59: Inventory | F59: [$k] | G59: =Assumptions!D49 -> 92500 | H59: {=_xlfn.ANCHORARRAY(H449)} -> 95370.275 | I59: 95465.55 | J59: 95560.825 | K59: 95656.1 | L59: 95751.375 | M59: 95846.65 | N59: 95941.925 | O59: 96037.2 | P59: 96132.475 | Q59: 96227.75 | R59: 96323.025 | S59: 96418.3 | T59: 99408.982 | U59: 99507.115 | V59: 99605.249 | W59: 99703.382 | X59: 99801.515 | Y59: 99899.648 | Z59: 99997.782 | AA59: 100095.91 | AB59: 100194.05 | AC59: 100292.18 | AD59: 100390.31 | AE59: 100488.45 | AF59: 103604.18 | AG59: 103705.26 | AH59: 103806.33 | AI59: 103907.41 | AJ59: 104008.49 | AK59: 104109.56 | AL59: 104210.64 | AM59: 104311.72 | AN59: 104412.8 | AO59: 104513.87 | AP59: 104614.95 | AQ59: 104716.03 | AR59: 107961.62 | AS59: 108065.73 | AT59: 108169.84 | AU59: 108273.95 | AV59: 108378.06 | AW59: 108482.17 | AX59: 108586.28 | AY59: 108690.39 | AZ59: 108794.5 | BA59: 108898.6 | BB59: 109002.71 | BC59: 109106.82 | BD59: 112487.26 | BE59: 112594.49 | BF59: 112701.73 | BG59: 112808.96 | BH59: 112916.19 | BI59: 113023.43 | BJ59: 113130.66 | BK59: 113237.89 | BL59: 113345.12 | BM59: 113452.36 | BN59: 113559.59 | BO59: 113666.82
...

Sheet Sheet1
A1: City | B1: Per Store Revenue | C1: Number of Stores
A2: Hexavale | B2: {=_xlfn.XLOOKUP(A2,_xlfn.ANCHORARRAY(Model!$C$218),Model!$BQ$218:$BQ$243)} -> 2449005.2 | C2: {=_xlfn.XLOOKUP(A2,_xlfn.ANCHORARRAY(Model!$C$127),Model!$BO$127:$BO$152)} -> 314
A3: Renderburg | B3: {=_xlfn.XLOOKUP(A3,_xlfn.ANCHORARRAY(Model!$C$218),Model!$BQ$218:$BQ$243)} -> 1470725.7 | C3: {=_xlfn.XLOOKUP(A3,_xlfn.ANCHORARRAY(Model!$C$127),Model!$BO$127:$BO$152)} -> 189
A4: Socket Springs | B4: {=_xlfn.XLOOKUP(A4,_xlfn.ANCHORARRAY(Model!$C$218),Model!$BQ$218:$BQ$243)} -> 1278666 | C4: {=_xlfn.XLOOKUP(A4,_xlfn.ANCHORARRAY(Model!$C$127),Model!$BO$127:$BO$152)} -> 170
A5: Gigatown | B5: {=_xlfn.XLOOKUP(A5,_xlfn.ANCHORARRAY(Model!$C$218),Model!$BQ$218:$BQ$243)} -> 508483.33 | C5: {=_xlfn.XLOOKUP(A5,_xlfn.ANCHORARRAY(Model!$C$127),Model!$BO$127:$BO$152)} -> 68
A6: TerraTask | B6: {=_xlfn.XLOOKUP(A6,_xlfn.ANCHORARRAY(Model!$C$218),Model!$BQ$218:$BQ$243)} -> 417908.49 | C6: {=_xlfn.XLOOKUP(A6,_xlfn.ANCHORARRAY(Model!$C$127),Model!$BO$127:$BO$152)} -> 57
A7: Overclock Oasis | B7: {=_xlfn.XLOOKUP(A7,_xlfn.ANCHORARRAY(Model!$C$218),Model!$BQ$218:$BQ$243)} -> 416192.2 | C7: {=_xlfn.XLOOKUP(A7,_xlfn.ANCHORARRAY(Model!$C$127),Model!$BO$127:$BO$152)} -> 53
A8: Bootwell | B8: {=_xlfn.XLOOKUP(A8,_xlfn.ANCHORARRAY(Model!$C$218),Model!$BQ$218:$BQ$243)} -> 243401.64 | C8: {=_xlfn.XLOOKUP(A8,_xlfn.ANCHORARRAY(Model!$C$127),Model!$BO$127:$BO$152)} -> 33
A9: Vector Valley | B9: {=_xlfn.XLOOKUP(A9,_xlfn.ANCHORARRAY(Model!$C$218),Model!$BQ$218:$BQ$243)} -> 212157.57 | C9: {=_xlfn.XLOOKUP(A9,_xlfn.ANCHORARRAY(Model!$C$127),Model!$BO$127:$BO$152)} -> 28
A10: Datahaven | B10: {=_xlfn.XLOOKUP(A10,_xlfn.ANCHORARRAY(Model!$C$218),Model!$BQ$218:$BQ$243)} -> 190514.39 | C10: {=_xlfn.XLOOKUP(A10,_xlfn.ANCHORARRAY(Model!$C$127),Model!$BO$127:$BO$152)} -> 25
A11: Input City | B11: {=_xlfn.XLOOKUP(A11,_xlfn.ANCHORARRAY(Model!$C$218),Model!$BQ$218:$BQ$243)} -> 139442.28 | C11: {=_xlfn.XLOOKUP(A11,_xlfn.ANCHORARRAY(Model!$C$127),Model!$BO$127:$BO$152)} -> 19
A12: Junction Core | B12: {=_xlfn.XLOOKUP(A12,_xlfn.ANCHORARRAY(Model!$C$218),Model!$BQ$218:$BQ$243)} -> 99717.996 | C12: {=_xlfn.XLOOKUP(A12,_xlfn.ANCHORARRAY(Model!$C$127),Model!$BO$127:$BO$152)} -> 10
A13: Quantum Quay | B13: {=_xlfn.XLOOKUP(A13,_xlfn.ANCHORARRAY(Model!$C$218),Model!$BQ$218:$BQ$243)} -> 72287.203 | C13: {=_xlfn.XLOOKUP(A13,_xlfn.ANCHORARRAY(Model!$C$127),Model!$BO$127:$BO$152)} -> 10
... A27: ZeroDay Zone | B27: {=_xlfn.XLOOKUP(A27,_xlfn.ANCHORARRAY(Model!$C$218),Model!$BQ$218:$BQ$243)} -> 10494.23 | C27: {=_xlfn.XLOOKUP(A27,_xlfn.ANCHORARRAY(Model!$C$127),Model!$BO$127:$BO$152)} -> 3

Sheet Model Validation
C2: Questions & Answers
B4: # | C4: Question | D4: Points | E4: Answer | F4: Answer | G4: Comment
B6: Part 1 (Operations)
B7: 1 | C7: Which city has the highest number of stores? | D7: =--(E7=F7) -> 1 | E7: {=_xlfn.XLOOKUP(MAX(Model!BO127:BO152),Model!BO127:BO152,_xlfn.ANCHORARRAY(Model!C127))} -> Hexavale | F7: Hexavale
B8: 2 | C8: Which store had the highest average monthly device sales in 2025? | D8: =--(E8=F8) -> 1 | E8: =_xlfn.XLOOKUP(MAX('Existing Stores'!F9:F1008),'Existing Stores'!F9:F1008,'Existing Stores'!C9:C1008) -> Gigatown Metro Center | F8: Gigatown Metro Center
B9: 3 | C9: How many stores will the company have at the end of Month 60 of calculations? | D9: =--(E9=F9) -> 1 | E9: =Model!BO153 -> 1060 | F9: 1060
B10: 4 | C10: What is the population per store of Bootwell in January 2026? | D10: =--(E10=F10) -> 1 | E10: =Model!H157 -> 18024 | F10: 18024
B11: 5 | C11: By month #60, how many cities will have their population per store fall to or below 10,000? | D11: =--(E11=F11) -> 1 | E11: =COUNTIF((Model!BO188:BO213),0.8) -> 6 | F11: 6
B12: 6 | C12: What were the average device sales per store in Axisbyte in 2025? | D12: =--(E12=F12) -> 1 | E12: =Model!E218 -> 121 | F12: 121
B13: 7 | C13: What will be the total device sales in all the 7 stores at Axisbyte in January 2026 (including the new store)? | D13: =--(E13=F13) -> 1 | E13: =Model!H218 -> 697.928 | F13: 697.928
B14: 8 | C14: What will be the total device sales in Axisbyte during the 60-month period? | D14: =--(E14=F14) -> 1 | E14: =SUM(Model!H218:BO218) -> 61724.456 | F14: 61724.456
B15: 9 | C15: What will be the total device sales in Cacheford during the 60-month period? | D15: =--(E15=F15) -> 1 | E15: =SUM(Model!H220:BO220) -> 35723.681 | F15: 35723.681
B16: 10 | C16: What are the total projected sales revenues during the 5-year period across all the 3 revenue groups? | D16: =--(E16=F16) -> 1 | E16: =ROUND(SUM(Model!H20:BO20),2) -> 8000721.9 | F16: =ROUND(8000721.86698094,2) -> 8000721.9
B17: 11 | C17: What is the projected hourly rate for sales assistants in 2030? | D17: =--(E17=F17) -> 1 | E17: =Model!BH326 -> 17.389111 | F17: 17.389111
B18: 12 | C18: How many sales personnel (FTE) will be employed in December of 2030? | D18: =--(E18=F18) -> 1 | E18: =Model!BO357 -> 3724 | F18: 3724
B19: 13 | C19: What is the total amount of rent & utilities that all the 7 stores in Axisbyte will be paying in January 2026? | D19: =--(E19=F19) -> 1 | E19: =Model!H363 -> 25.661147 | F19: 25.661147
B20: 14 | C20: What is the total EBITDA of AFM over the 5-year period? | D20: =--(E20=F20) -> 1 | E20: =SUM(_xlfn.ANCHORARRAY(Model!H38)) -> 620332.42 | F20: 620332.42
B22: Part 2 (Financials)
B23: 15 | C23: What is the projected amount of the Accounts Receivable for AFM at the end of January 2026? | D23: =--(E23=F23) -> 1 | E23: =Model!H58 -> 48733.434 | F23: 48733.434
B24: 16 | C24: What is the projected amount of the inventory at the end of 2030? | D24: =--(E24=F24) -> 1 | E24: =Model!BO59 -> 113666.82 | F24: 113666.82
B25: 17 | C25: What is the projected amount of the Accounts Payable (excluding tax payable) at the end of 2030? | D25: =--(E25=F25) -> 1 | E25: =-Model!BO450 -> 189093.64 | F25: 189093.64
B26: 18 | C26: What is the total nominal CAPEX that TeleKings will spend over the 5-year period? | D26: =--(E26=F26) -> 1 | E26: =SUM(_xlfn.ANCHORARRAY(Model!H471)) -> 6562.0919 | F26: 6562.0919
B27: 19 | C27: What is the total amortization expense for intangible assets in January 2026? | D27: =--(E27=F27) -> 1 | E27: =-Model!H478 -> 27.777778 | F27: 27.777778
B28: 20 | C28: What is the total depreciation expense for TeleKings fixed assets (excluding the intangible assets) over the 5-year period? | D28: =--(E28=F28) -> 1 | E28: =SUM(Model!H92:BO92) -> 103148.8 | F28: 103148.8
B29: 21 | C29: What is the interest expense for the variable rate subordinate debt during the 5-year period? | D29: =--(E29=F29) -> 1 | E29: =SUM(Model!H499:BO499) -> 2871.75 | F29: 2871.75
B30: 22 | C30: After you put together TeleKings starting balance sheet, what is the value of Retained Earnings as of Dec 31, 2025? | D30: =--(E30=F30) -> 1 | E30: =Model!G84 -> 70500 | F30: 70500
B31: 23 | C31: What will be the first amount drawn from the revolving line of credit (this will happen in January 2026)? | D31: =--(E31=F31) -> 1 | E31: =Model!H503 -> 7614.8283 | F31: 7614.8283
B32: 24 | C32: When will TeleKings fully repay their revolving line of credit? | D32: =--(E32=F32) -> 1 | E32: =Model!J8 -> 46112 | F32: 46112
B33: 25 | C33: What are the AFM's retained earnings at the end of 2030 (after paying the dividends for the month)? | D33: =--(E33=F33) -> 1 | E33: =Model!BO536 -> 272052.98 | F33: 272052.98
B34: 26 | C34: Assume that instead of opening stores that bring cannibalization penalties to sales, you skip them and instead open the next store in sequence. Under this scenario, what are the Retained Earnings at the end of 2030? | D34: =--(E34=F34) -> 0 | F34: 274844.83
